I'm sorry, but an uncaught exception occurred.

While running game code:
Exception: DynamicImage ['gui/confirm_frame.png', 'gui/frame.png']: could not find image. ('gui/confirm_frame.png', 'gui/frame.png')

-- Full Traceback ------------------------------------------------------------

Full traceback:
  File "renpy/common/_layout/screen_load_save.rpym", line 35, in script
    $ ui.interact()
  File "C:\Users\charles\Downloads\renpy-8.3.3-sdk\renpy\ast.py", line 821, in execute
    renpy.python.py_exec_bytecode(self.code.bytecode, self.hide, store=self.store)
  File "C:\Users\charles\Downloads\renpy-8.3.3-sdk\renpy\python.py", line 1178, in py_exec_bytecode
    exec(bytecode, globals, locals)
  File "renpy/common/_layout/screen_load_save.rpym", line 35, in <module>
    $ ui.interact()
  File "C:\Users\charles\Downloads\renpy-8.3.3-sdk\renpy\ui.py", line 301, in interact
    rv = renpy.game.interface.interact(roll_forward=roll_forward, **kwargs)
  File "C:\Users\charles\Downloads\renpy-8.3.3-sdk\renpy\display\core.py", line 2215, in interact
    repeat, rv = self.interact_core(preloads=preloads, trans_pause=trans_pause, pause=pause, pause_start=pause_start, pause_modal=pause_modal, **kwargs) # type: ignore
  File "C:\Users\charles\Downloads\renpy-8.3.3-sdk\renpy\display\core.py", line 2745, in interact_core
    root_widget.visit_all(lambda d : d.per_interact())
  File "C:\Users\charles\Downloads\renpy-8.3.3-sdk\renpy\display\displayable.py", line 434, in visit_all
    d.visit_all(callback, seen)
  File "C:\Users\charles\Downloads\renpy-8.3.3-sdk\renpy\display\displayable.py", line 434, in visit_all
    d.visit_all(callback, seen)
  File "C:\Users\charles\Downloads\renpy-8.3.3-sdk\renpy\display\displayable.py", line 434, in visit_all
    d.visit_all(callback, seen)
  File "C:\Users\charles\Downloads\renpy-8.3.3-sdk\renpy\display\screen.py", line 485, in visit_all
    self.child.visit_all(callback, seen=None)
  File "C:\Users\charles\Downloads\renpy-8.3.3-sdk\renpy\display\displayable.py", line 434, in visit_all
    d.visit_all(callback, seen)
  File "C:\Users\charles\Downloads\renpy-8.3.3-sdk\renpy\display\displayable.py", line 434, in visit_all
    d.visit_all(callback, seen)
  File "C:\Users\charles\Downloads\renpy-8.3.3-sdk\renpy\display\displayable.py", line 434, in visit_all
    d.visit_all(callback, seen)
  File "C:\Users\charles\Downloads\renpy-8.3.3-sdk\renpy\display\displayable.py", line 424, in visit_all
    for d in self.visit():
  File "C:\Users\charles\Downloads\renpy-8.3.3-sdk\renpy\display\image.py", line 785, in visit
    self.find_target()
  File "C:\Users\charles\Downloads\renpy-8.3.3-sdk\renpy\display\image.py", line 683, in find_target
    raise Exception(error)
Exception: DynamicImage ['gui/confirm_frame.png', 'gui/frame.png']: could not find image. ('gui/confirm_frame.png', 'gui/frame.png')

Windows-10-10.0.22631 AMD64
Ren'Py 8.3.3.24111502
APOCALYPSE 1.0
Sat Nov 30 19:42:12 2024
